<?xml version="1.0"?>
<robot name="so101" xmlns:xacro="http://www.ros.org/wiki/xacro">

  <!-- BASE -->
  <link name="base_link"/>

  <!-- LINK1 -->
  <link name="link1"/>
  <joint name="joint1" type="revolute">
    <parent link="base_link"/>
    <child link="link1"/>
    <origin xyz="0 0 0.05"/>
    <axis xyz="0 0 1"/>
    <limit lower="-3.14" upper="3.14" effort="10" velocity="1"/>
  </joint>

  <!-- LINK2 -->
  <link name="link2"/>
  <joint name="joint2" type="revolute">
    <parent link="link1"/>
    <child link="link2"/>
    <origin xyz="0 0 0.1"/>
    <axis xyz="0 1 0"/>
    <limit lower="-1.57" upper="1.57" effort="10" velocity="1"/>
  </joint>

  <!-- LINK3 -->
  <link name="link3"/>
  <joint name="joint3" type="revolute">
    <parent link="link2"/>
    <child link="link3"/>
    <origin xyz="0 0 0.1"/>
    <axis xyz="0 1 0"/>
    <limit lower="-1.57" upper="1.57" effort="10" velocity="1"/>
  </joint>

  <!-- LINK4 (END) -->
  <link name="link4"/>
  <joint name="joint4" type="revolute">
    <parent link="link3"/>
    <child link="link4"/>
    <origin xyz="0 0 0.1"/>
    <axis xyz="0 1 0"/>
    <limit lower="-1.57" upper="1.57" effort="10" velocity="1"/>
  </joint>

  <ros2_control name="FakeSystem" type="system">
    <hardware>
      <plugin>mock_components/GenericSystem</plugin>
    </hardware>
  
    <joint name="joint1">
      <command_interface name="position"/>
      <state_interface name="position"/>
    </joint>
    <joint name="joint2">
      <command_interface name="position"/>
      <state_interface name="position"/>
    </joint>
    <joint name="joint3">
      <command_interface name="position"/>
      <state_interface name="position"/>
    </joint>
    <joint name="joint4">
      <command_interface name="position"/>
      <state_interface name="position"/>
    </joint>
  </ros2_control>

</robot>
